Workbook
Name Slicer_Category: #N/A
Name Slicer_City: #N/A
Name Slicer_Gender: #N/A
Name Slicer_Month: #N/A
Name Slicer_Occasion: #N/A
Name Slicer_Order_Value_Category: #N/A

Sheet orders
A1: Order_ID | B1: Customer_ID | C1: Product_ID | D1: Quantity | E1: Order_Date | F1: Order_Time | G1: Delivery_Date | H1: Delivery_Time | I1: Location | J1: Occasion | K1: Number of days for delivery | L1: Quantity_Check | M1: Date_Check
A2: 1 | B2: C037 | C2: 67 | D2: 5 | E2: 44981 | F2: 0.99181713 | G2: 44990 | H2: 0.31053241 | I2: Bardhaman | J2: Anniversary | K2: 9 | L2: =IF(tblOrders[[#This Row],[Quantity]]<=0,"Check","OK") -> OK | M2: =IF(tblOrders[[#This Row],[Delivery_Date]]<tblOrders[[#This Row],[Order_Date]],"Error","OK") -> OK
A3: 2 | B3: C019 | C3: 41 | D3: 2 | E3: 45237 | F3: 0.979375 | G3: 45243 | H3: 0.30297454 | I3: Jaipur | J3: Diwali | K3: 6 | L3: =IF(tblOrders[[#This Row],[Quantity]]<=0,"Check","OK") -> OK | M3: =IF(tblOrders[[#This Row],[Delivery_Date]]<tblOrders[[#This Row],[Order_Date]],"Error","OK") -> OK
A4: 3 | B4: C029 | C4: 67 | D4: 5 | E4: 45121 | F4: 0.80003472 | G4: 45126 | H4: 0.73541667 | I4: Bilaspur | J4: Anniversary | K4: 5 | L4: =IF(tblOrders[[#This Row],[Quantity]]<=0,"Check","OK") -> OK | M4: =IF(tblOrders[[#This Row],[Delivery_Date]]<tblOrders[[#This Row],[Order_Date]],"Error","OK") -> OK
A5: 4 | B5: C012 | C5: 14 | D5: 5 | E5: 45117 | F5: 0.19755787 | G5: 45126 | H5: 0.27318287 | I5: Guwahati | J5: Birthday | K5: 9 | L5: =IF(tblOrders[[#This Row],[Quantity]]<=0,"Check","OK") -> OK | M5: =IF(tblOrders[[#This Row],[Delivery_Date]]<tblOrders[[#This Row],[Order_Date]],"Error","OK") -> OK
A6: 5 | B6: C078 | C6: 58 | D6: 2 | E6: 44968 | F6: 0.82277778 | G6: 44975 | H6: 0.46449074 | I6: Rajkot | J6: Valentine's Day | K6: 7 | L6: =IF(tblOrders[[#This Row],[Quantity]]<=0,"Check","OK") -> OK | M6: =IF(tblOrders[[#This Row],[Delivery_Date]]<tblOrders[[#This Row],[Order_Date]],"Error","OK") -> OK
A7: 6 | B7: C040 | C7: 28 | D7: 4 | E7: 45158 | F7: 0.92471065 | G7: 45164 | H7: 0.79636574 | I7: Sirsa | J7: Raksha Bandhan | K7: 6 | L7: =IF(tblOrders[[#This Row],[Quantity]]<=0,"Check","OK") -> OK | M7: =IF(tblOrders[[#This Row],[Delivery_Date]]<tblOrders[[#This Row],[Order_Date]],"Error","OK") -> OK
A8: 7 | B8: C009 | C8: 45 | D8: 2 | E8: 45054 | F8: 0.07306713 | G8: 45059 | H8: 0.42172454 | I8: Nanded | J8: Birthday | K8: 5 | L8: =IF(tblOrders[[#This Row],[Quantity]]<=0,"Check","OK") -> OK | M8: =IF(tblOrders[[#This Row],[Delivery_Date]]<tblOrders[[#This Row],[Order_Date]],"Error","OK") -> OK
A9: 8 | B9: C097 | C9: 43 | D9: 3 | E9: 45238 | F9: 0.8055787 | G9: 45244 | H9: 0.36440972 | I9: Morena | J9: Diwali | K9: 6 | L9: =IF(tblOrders[[#This Row],[Quantity]]<=0,"Check","OK") -> OK | M9: =IF(tblOrders[[#This Row],[Delivery_Date]]<tblOrders[[#This Row],[Order_Date]],"Error","OK") -> OK
A10: 9 | B10: C044 | C10: 27 | D10: 4 | E10: 45158 | F10: 0.98600694 | G10: 45167 | H10: 0.99993056 | I10: Rajkot | J10: Raksha Bandhan | K10: 9 | L10: =IF(tblOrders[[#This Row],[Quantity]]<=0,"Check","OK") -> OK | M10: =IF(tblOrders[[#This Row],[Delivery_Date]]<tblOrders[[#This Row],[Order_Date]],"Error","OK") -> OK
A11: 10 | B11: C099 | C11: 56 | D11: 3 | E11: 44983 | F11: 0.012106481 | G11: 44993 | H11: 0.86646991 | I11: Ambala | J11: Anniversary | K11: 10 | L11: =IF(tblOrders[[#This Row],[Quantity]]<=0,"Check","OK") -> OK | M11: =IF(tblOrders[[#This Row],[Delivery_Date]]<tblOrders[[#This Row],[Order_Date]],"Error","OK") -> OK
A12: 11 | B12: C065 | C12: 16 | D12: 4 | E12: 44987 | F12: 0.84369213 | G12: 44988 | H12: 0.97207176 | I12: Belgaum | J12: Holi | K12: 1 | L12: =IF(tblOrders[[#This Row],[Quantity]]<=0,"Check","OK") -> OK | M12: =IF(tblOrders[[#This Row],[Delivery_Date]]<tblOrders[[#This Row],[Order_Date]],"Error","OK") -> OK
A13: 12 | B13: C097 | C13: 38 | D13: 3 | E13: 45119 | F13: 0.35342593 | G13: 45127 | H13: 0.98260417 | I13: Karnal | J13: Birthday | K13: 8 | L13: =IF(tblOrders[[#This Row],[Quantity]]<=0,"Check","OK") -> OK | M13: =IF(tblOrders[[#This Row],[Delivery_Date]]<tblOrders[[#This Row],[Order_Date]],"Error","OK") -> OK
... A1001: 1000 | B1001: C012 | C1001: 27 | D1001: 4 | E1001: 45163 | F1001: 0.05744213 | G1001: 45169 | H1001: 0.2902662 | I1001: Tadepalligudem | J1001: Raksha Bandhan | K1001: 6 | L1001: =IF(tblOrders[[#This Row],[Quantity]]<=0,"Check","OK") -> OK | M1001: =IF(tblOrders[[#This Row],[Delivery_Date]]<tblOrders[[#This Row],[Order_Date]],"Error","OK") -> OK

Sheet customers
A1: Customer_ID | B1: Name | C1: City | D1: Contact_Number | E1: Email | F1: Gender | G1: Address
A2: C001 | B2: Tara Krishnan | C2: Panchkula | D2: +917193971454 | E2: mandrati@chad.org | F2: Female | G2: 65/04 Dhawan Marg, Rajpur Sonarpur 590551
A3: C002 | B3: Myra Edwin | C3: Bulandshahr | D3: 08915420519 | E3: yshukla@hotmail.com | F3: Female | G3: H.No. 78 Sharaf Ganj Indore 928261
A4: C003 | B4: Jayesh Lanka | C4: Bilaspur | D4: 07400208126 | E4: kavyabarad@hotmail.com | F4: Male | G4: H.No. 53, Krishna Ganj, Dhule-346480
A5: C004 | B5: Tarini Bava | C5: Miryalaguda | D5: 07232349928 | E5: vsen@hotmail.com | F5: Male | G5: 145 Sibal, Rourkela-650344 | K5: =COUNTBLANK(A2:G101) -> 0
A6: C005 | B6: Hiran Kaul | C6: Kottayam | D6: 02207644242 | E6: hanshkapur@buch.biz | F6: Male | G6: 34/168 Sachar Street Bhatpara 002691
A7: C006 | B7: Rania Mann | C7: Karimnagar | D7: +919363577179 | E7: evaswamy@biswas-sekhon.com | F7: Female | G7: 15/89, Dayal Chowk, Rohtak 586046
A8: C007 | B8: Jayant Kamdar | C8: Berhampore | D8: +918576675504 | E8: pcontractor@hotmail.com | F8: Male | G8: H.No. 501 Goswami Path, Bhilwara 482554
A9: C008 | B9: Veer Ray | C9: Chinsurah | D9: 7138085704 | E9: uthkarshjohal@yahoo.com | F9: Female | G9: H.No. 589, Gala Circle, Nandyal-774484
A10: C009 | B10: Ritvik Borah | C10: Madurai | D10: 1336765676 | E10: daliajivika@yahoo.com | F10: Female | G10: 28/64 Lanka Marg, Ramgarh 141634
A11: C010 | B11: Darshit Dave | C11: Kanpur | D11: 01608833065 | E11: fateh26@hotmail.com | F11: Male | G11: H.No. 21 Singhal Path Hindupur 170985
A12: C011 | B12: Lagan Kapoor | C12: Orai | D12: +916173563562 | E12: rsidhu@gmail.com | F12: Female | G12: 53/710, Tailor Ganj, Gorakhpur-030540
A13: C012 | B13: Onkar Mangat | C13: Bilaspur | D13: +919921125624 | E13: oorjabassi@wali.com | F13: Male | G13: H.No. 460, Sankar Ganj Tadipatri 227246
A14: C013 | B14: Manikya Goswami | C14: Mangalore | D14: +912112817503 | E14: settytara@gmail.com | F14: Female | G14: 382, Banerjee Ganj Patna 002103
A15: C014 | B15: Indrans Shukla | C15: Panvel | D15: 2717671919 | E15: rajagopalfateh@dhingra.info | F15: Female | G15: 67/61, Balan Nagar Dehri-162882
A16: C015 | B16: Romil Bajwa | C16: Kolkata | D16: +918664164910 | E16: taimurkashyap@halder.com | F16: Female | G16: 890, Sathe Circle Moradabad 800838
A17: C016 | B17: Amani Ganesh | C17: Tenali | D17: 08482992702 | E17: sumerkaur@yahoo.com | F17: Male | G17: 667 Som Marg Rajkot 238865
... A101: C100 | B101: Pranay Chaudhary | C101: Phagwara | D101: +919478540370 | E101: prisha77@loke.org | F101: Female | G101: H.No. 58 Sem Street, Amravati 316691

Sheet products
A1: Product_ID | B1: Product_Name | C1: Category | D1: Price (INR) | E1: Occasion | F1: Description | G1: Price_Check
A2: 1 | B2: Magnam Set | C2: Soft Toys | D2: 1935 | E2: All Occasions | F2: Quam numquam iste sunt nemo. | G2: =IF(tblProducts[[#This Row],[Price (INR)]]<=0,"Check","OK") -> OK
A3: 2 | B3: Voluptas Box | C3: Plants | D3: 441 | E3: Valentine's Day | F3: At quaerat animi nemo. | G3: =IF(tblProducts[[#This Row],[Price (INR)]]<=0,"Check","OK") -> OK
A4: 3 | B4: Eius Gift | C4: Colors | D4: 1534 | E4: Valentine's Day | F4: Deserunt pariatur mollitia voluptatem. | G4: =IF(tblProducts[[#This Row],[Price (INR)]]<=0,"Check","OK") -> OK
A5: 4 | B5: Accusantium Set | C5: Sweets | D5: 1199 | E5: Diwali | F5: Corporis odio consequatur perferendis repellendus laudantium deserunt. | G5: =IF(tblProducts[[#This Row],[Price (INR)]]<=0,"Check","OK") -> OK
A6: 5 | B6: Natus Gift | C6: Colors | D6: 1444 | E6: All Occasions | F6: Quis occaecati reprehenderit facere tenetur illum exercitationem. | G6: =IF(tblProducts[[#This Row],[Price (INR)]]<=0,"Check","OK") -> OK
A7: 6 | B7: Quos Box | C7: Cake | D7: 1112 | E7: Holi | F7: Eum deleniti adipisci vero neque. | G7: =IF(tblProducts[[#This Row],[Price (INR)]]<=0,"Check","OK") -> OK | I7: =COUNTBLANK(tblProducts[]) -> 0
A8: 7 | B8: Quos Set | C8: Soft Toys | D8: 409 | E8: Holi | F8: Sint accusamus veritatis exercitationem corporis. | G8: =IF(tblProducts[[#This Row],[Price (INR)]]<=0,"Check","OK") -> OK
A9: 8 | B9: Qui Box | C9: Sweets | D9: 252 | E9: Anniversary | F9: Praesentium necessitatibus quos esse neque. | G9: =IF(tblProducts[[#This Row],[Price (INR)]]<=0,"Check","OK") -> OK
A10: 9 | B10: Aperiam Box | C10: Colors | D10: 1605 | E10: Raksha Bandhan | F10: Explicabo totam quaerat a quaerat ducimus officia. | G10: =IF(tblProducts[[#This Row],[Price (INR)]]<=0,"Check","OK") -> OK
A11: 10 | B11: Accusantium Gift | C11: Cake | D11: 259 | E11: Birthday | F11: Minima nobis repellendus distinctio a veritatis voluptate eaque. | G11: =IF(tblProducts[[#This Row],[Price (INR)]]<=0,"Check","OK") -> OK
A12: 11 | B12: Maxime Set | C12: Mugs | D12: 1096 | E12: Valentine's Day | F12: Sapiente exercitationem illo sed ea. | G12: =IF(tblProducts[[#This Row],[Price (INR)]]<=0,"Check","OK") -> OK
A13: 12 | B13: Non Set | C13: Plants | D13: 672 | E13: Anniversary | F13: Fugiat id similique minima corrupti ut sint sapiente. | G13: =IF(tblProducts[[#This Row],[Price (INR)]]<=0,"Check","OK") -> OK
A14: 13 | B14: Et Set | C14: Mugs | D14: 1141 | E14: Holi | F14: Eius praesentium ipsum autem. | G14: =IF(tblProducts[[#This Row],[Price (INR)]]<=0,"Check","OK") -> OK
A15: 14 | B15: Deserunt Box | C15: Colors | D15: 1915 | E15: Birthday | F15: Incidunt hic vero esse saepe illum. | G15: =IF(tblProducts[[#This Row],[Price (INR)]]<=0,"Check","OK") -> OK
A16: 15 | B16: Repudiandae Box | C16: Raksha Bandhan | D16: 1488 | E16: Anniversary | F16: Consequuntur placeat quia voluptate esse consectetur accusamus nemo. | G16: =IF(tblProducts[[#This Row],[Price (INR)]]<=0,"Check","OK") -> OK
A17: 16 | B17: Ut Pack | C17: Sweets | D17: 1721 | E17: Holi | F17: Quae occaecati laborum expedita perspiciatis consequatur ad. | G17: =IF(tblProducts[[#This Row],[Price (INR)]]<=0,"Check","OK") -> OK
A18: 17 | B18: Delectus Gift | C18: Soft Toys | D18: 1899 | E18: Anniversary | F18: Architecto beatae ullam ad sed dolorem voluptates est. | G18: =IF(tblProducts[[#This Row],[Price (INR)]]<=0,"Check","OK") -> OK
A19: 18 | B19: Nemo Set | C19: Plants | D19: 781 | E19: Birthday | F19: Perspiciatis nemo dolorem perspiciatis aspernatur. | G19: =IF(tblProducts[[#This Row],[Price (INR)]]<=0,"Check","OK") -> OK
... A71: 70 | B71: Error Gift | C71: Sweets | D71: 866 | E71: Birthday | F71: Debitis provident illo aliquam debitis. | G71: =IF(tblProducts[[#This Row],[Price (INR)]]<=0,"Check","OK") -> OK

Sheet Project_Info
A1: Dataset Info
A3: Metric | B3: Value
A4: Number of Orders | B4: =ROWS(tblOrders[]) -> 1000
A5: Number of Customers | B5: =ROWS(tblCustomers[]) -> 100
A6: Number of Products | B6: =ROWS(tblProducts[]) -> 70
A7: Order Date Range
A8: Number of Cities | B8: =COUNTA(_xlfn.UNIQUE(tblCustomers[City])) -> 86
A9: Number of Product Categories | B9: =COUNTA(_xlfn.UNIQUE(tblProducts[Category])) -> 7
A10: Number of Occasions | B10: =COUNTA(_xlfn.UNIQUE(tblOrders[Occasion])) -> 7
A13: Column | B13: Values
A14: Duplicate Orders | B14: 0
A15: Duplicate Customers | B15: 0
A16: Duplicate Products | B16: 0
A17: Missing Order ID | B17: =COUNTBLANK(tblOrders[Order_ID]) -> 0
A18: Missing Customer ID | B18: =COUNTBLANK(tblCustomers[Customer_ID]) -> 0
A19: Missing Product ID | B19: =COUNTBLANK(tblProducts[Product_ID]) -> 0
A20: Missing Quantities | B20: =COUNTBLANK(tblOrders[Quantity]) -> 0
A21: Missing Order Date | B21: =COUNTBLANK(tblOrders[Order_Date]) -> 0
A22: Missing Delivery Date | B22: =COUNTBLANK(tblOrders[Delivery_Date]) -> 0
A23: Invalid Dates | B23: 0
A24: Invalid Quantities | B24: 0
A25: Invalid Prices | B25: 0

Sheet Cleaned Data
A1: Order_ID | B1: Customer_ID | C1: Product_ID | D1: Quantity | E1: Order_Date | F1: Order_Time | G1: Delivery_Date | H1: Delivery_Time | I1: Location | J1: Occasion | K1: City | L1: Customer Name | M1: Gender | N1: Product Name | O1: Category | P1: Occasion2 | Q1: Price | R1: Revenue | S1: Estimated Cost (at 70%) | T1: Profit | U1: Profit Margin | V1: Delivery Time | W1: Month | X1: Month Number | Y1: Quarter | Z1: Year | AA1: Day of Week | AB1: Order Value Category
A2: 1 | B2: C037 | C2: 67 | D2: 5 | E2: 44981 | F2: 0.99181713 | G2: 44990 | H2: 0.31053241 | I2: Bardhaman | J2: Anniversary | K2: =_xlfn.XLOOKUP(tblMaster[[#This Row],[Customer_ID]],tblCustomers[Customer_ID],tblCustomers[City],"Not Found",0) -> Davanagere | L2: =_xlfn.XLOOKUP(tblMaster[[#This Row],[Customer_ID]],tblCustomers[Customer_ID],tblCustomers[Name],"Not Found",0) -> Aradhya Kumar | M2: =_xlfn.XLOOKUP(tblMaster[[#This Row],[Customer_ID]],tblCustomers[Customer_ID],tblCustomers[Gender],"Not Found",0) -> Male | N2: =_xlfn.XLOOKUP(tblMaster[[#This Row],[Product_ID]],tblProducts[Product_ID],tblProducts[Product_Name],"Not Found",0) -> Maiores Box | O2: =_xlfn.XLOOKUP(tblMaster[[#This Row],[Product_ID]],tblProducts[Product_ID],tblProducts[Category],"Not Found",0) -> Raksha Bandhan | P2: =_xlfn.XLOOKUP(tblMaster[[#This Row],[Product_ID]],tblProducts[Product_ID],tblProducts[Occasion],"Not Found",0) -> Anniversary | Q2: =_xlfn.XLOOKUP(tblMaster[[#This Row],[Product_ID]],tblProducts[Product_ID],tblProducts[Price (INR)],"Not Found",0) -> 1374 | R2: =tblMaster[[#This Row],[Price]]*tblMaster[[#This Row],[Quantity]] -> 6870 | S2: =tblMaster[[#This Row],[Price]]*0.7*tblMaster[[#This Row],[Quantity]] -> 4809 | T2: =tblMaster[[#This Row],[Revenue]]-tblMaster[[#This Row],[Estimated Cost (at 70%) ]] -> 2061 | U2: =tblMaster[[#This Row],[Profit]]/tblMaster[[#This Row],[Revenue]] -> 0.3 | V2: =tblMaster[[#This Row],[Delivery_Date]]-tblMaster[[#This Row],[Order_Date]] -> 9 | W2: =TEXT(tblMaster[[#This Row],[Order_Date]],"mmmm") -> February | X2: =MONTH(tblMaster[[#This Row],[Order_Date]]) -> 2 | Y2: ="Q"&ROUNDUP(tblMaster[[#This Row],[Month Number]]/3,0) -> Q1 | Z2: =YEAR(tblMaster[[#This Row],[Order_Date]]) -> 2023 | AA2: =TEXT(DAY(tblMaster[[#This Row],[Order_Date]]),"dddd") -> Tuesday | AB2: =IF(tblMaster[[#This Row],[Revenue]]>=5000,"High",IF(tblMaster[[#This Row],[Revenue]]<2000,"Low","Medium")) -> High
A3: 2 | B3: C019 | C3: 41 | D3: 2 | E3: 45237 | F3: 0.979375 | G3: 45243 | H3: 0.30297454 | I3: Jaipur | J3: Diwali | K3: =_xlfn.XLOOKUP(tblMaster[[#This Row],[Customer_ID]],tblCustomers[Customer_ID],tblCustomers[City],"Not Found",0) -> Danapur | L3: =_xlfn.XLOOKUP(tblMaster[[#This Row],[Customer_ID]],tblCustomers[Customer_ID],tblCustomers[Name],"Not Found",0) -> Amira Sengupta | M3: =_xlfn.XLOOKUP(tblMaster[[#This Row],[Customer_ID]],tblCustomers[Customer_ID],tblCustomers[Gender],"Not Found",0) -> Male | N3: =_xlfn.XLOOKUP(tblMaster[[#This Row],[Product_ID]],tblProducts[Product_ID],tblProducts[Product_Name],"Not Found",0) -> Aut Box | O3: =_xlfn.XLOOKUP(tblMaster[[#This Row],[Product_ID]],tblProducts[Product_ID],tblProducts[Category],"Not Found",0) -> Sweets | P3: =_xlfn.XLOOKUP(tblMaster[[#This Row],[Product_ID]],tblProducts[Product_ID],tblProducts[Occasion],"Not Found",0) -> Diwali | Q3: =_xlfn.XLOOKUP(tblMaster[[#This Row],[Product_ID]],tblProducts[Product_ID],tblProducts[Price (INR)],"Not Found",0) -> 1977 | R3: =tblMaster[[#This Row],[Price]]*tblMaster[[#This Row],[Quantity]] -> 3954 | S3: =tblMaster[[#This Row],[Price]]*0.7*tblMaster[[#This Row],[Quantity]] -> 2767.8 | T3: =tblMaster[[#This Row],[Revenue]]-tblMaster[[#This Row],[Estimated Cost (at 70%) ]] -> 1186.2 | U3: =tblMaster[[#This Row],[Profit]]/tblMaster[[#This Row],[Revenue]] -> 0.3 | V3: =tblMaster[[#This Row],[Delivery_Date]]-tblMaster[[#This Row],[Order_Date]] -> 6 | W3: =TEXT(tblMaster[[#This Row],[Order_Date]],"mmmm") -> November | X3: =MONTH(tblMaster[[#This Row],[Order_Date]]) -> 11 | Y3: ="Q"&ROUNDUP(tblMaster[[#This Row],[Month Number]]/3,0) -> Q4 | Z3: =YEAR(tblMaster[[#This Row],[Order_Date]]) -> 2023 | AA3: =TEXT(DAY(tblMaster[[#This Row],[Order_Date]]),"dddd") -> Saturday | AB3: =IF(tblMaster[[#This Row],[Revenue]]>=5000,"High",IF(tblMaster[[#This Row],[Revenue]]<2000,"Low","Medium")) -> Medium
A4: 3 | B4: C029 | C4: 67 | D4: 5 | E4: 45121 | F4: 0.80003472 | G4: 45126 | H4: 0.73541667 | I4: Bilaspur | J4: Anniversary | K4: =_xlfn.XLOOKUP(tblMaster[[#This Row],[Customer_ID]],tblCustomers[Customer_ID],tblCustomers[City],"Not Found",0) -> Haridwar | L4: =_xlfn.XLOOKUP(tblMaster[[#This Row],[Customer_ID]],tblCustomers[Customer_ID],tblCustomers[Name],"Not Found",0) -> Badal Sathe | M4: =_xlfn.XLOOKUP(tblMaster[[#This Row],[Customer_ID]],tblCustomers[Customer_ID],tblCustomers[Gender],"Not Found",0) -> Female | N4: =_xlfn.XLOOKUP(tblMaster[[#This Row],[Product_ID]],tblProducts[Product_ID],tblProducts[Product_Name],"Not Found",0) -> Maiores Box | O4: =_xlfn.XLOOKUP(tblMaster[[#This Row],[Product_ID]],tblProducts[Product_ID],tblProducts[Category],"Not Found",0) -> Raksha Bandhan | P4: =_xlfn.XLOOKUP(tblMaster[[#This Row],[Product_ID]],tblProducts[Product_ID],tblProducts[Occasion],"Not Found",0) -> Anniversary | Q4: =_xlfn.XLOOKUP(tblMaster[[#This Row],[Product_ID]],tblProducts[Product_ID],tblProducts[Price (INR)],"Not Found",0) -> 1374 | R4: =tblMaster[[#This Row],[Price]]*tblMaster[[#This Row],[Quantity]] -> 6870 | S4: =tblMaster[[#This Row],[Price]]*0.7*tblMaster[[#This Row],[Quantity]] -> 4809 | T4: =tblMaster[[#This Row],[Revenue]]-tblMaster[[#This Row],[Estimated Cost (at 70%) ]] -> 2061 | U4: =tblMaster[[#This Row],[Profit]]/tblMaster[[#This Row],[Revenue]] -> 0.3 | V4: =tblMaster[[#This Row],[Delivery_Date]]-tblMaster[[#This Row],[Order_Date]] -> 5 | W4: =TEXT(tblMaster[[#This Row],[Order_Date]],"mmmm") -> July | X4: =MONTH(tblMaster[[#This Row],[Order_Date]]) -> 7 | Y4: ="Q"&ROUNDUP(tblMaster[[#This Row],[Month Number]]/3,0) -> Q3 | Z4: =YEAR(tblMaster[[#This Row],[Order_Date]]) -> 2023 | AA4: =TEXT(DAY(tblMaster[[#This Row],[Order_Date]]),"dddd") -> Saturday | AB4: =IF(tblMaster[[#This Row],[Revenue]]>=5000,"High",IF(tblMaster[[#This Row],[Revenue]]<2000,"Low","Medium")) -> High
A5: 4 | B5: C012 | C5: 14 | D5: 5 | E5: 45117 | F5: 0.19755787 | G5: 45126 | H5: 0.27318287 | I5: Guwahati | J5: Birthday | K5: =_xlfn.XLOOKUP(tblMaster[[#This Row],[Customer_ID]],tblCustomers[Customer_ID],tblCustomers[City],"Not Found",0) -> Bilaspur | L5: =_xlfn.XLOOKUP(tblMaster[[#This Row],[Customer_ID]],tblCustomers[Customer_ID],tblCustomers[Name],"Not Found",0) -> Onkar Mangat | M5: =_xlfn.XLOOKUP(tblMaster[[#This Row],[Customer_ID]],tblCustomers[Customer_ID],tblCustomers[Gender],"Not Found",0) -> Male | N5: =_xlfn.XLOOKUP(tblMaster[[#This Row],[Product_ID]],tblProducts[Product_ID],tblProducts[Product_Name],"Not Found",0) -> Deserunt Box | O5: =_xlfn.XLOOKUP(tblMaster[[#This Row],[Product_ID]],tblProducts[Product_ID],tblProducts[Category],"Not Found",0) -> Colors | P5: =_xlfn.XLOOKUP(tblMaster[[#This Row],[Product_ID]],tblProducts[Product_ID],tblProducts[Occasion],"Not Found",0) -> Birthday | Q5: =_xlfn.XLOOKUP(tblMaster[[#This Row],[Product_ID]],tblProducts[Product_ID],tblProducts[Price (INR)],"Not Found",0) -> 1915 | R5: =tblMaster[[#This Row],[Price]]*tblMaster[[#This Row],[Quantity]] -> 9575 | S5: =tblMaster[[#This Row],[Price]]*0.7*tblMaster[[#This Row],[Quantity]] -> 6702.5 | T5: =tblMaster[[#This Row],[Revenue]]-tblMaster[[#This Row],[Estimated Cost (at 70%) ]] -> 2872.5 | U5: =tblMaster[[#This Row],[Profit]]/tblMaster[[#This Row],[Revenue]] -> 0.3 | V5: =tblMaster[[#This Row],[Delivery_Date]]-tblMaster[[#This Row],[Order_Date]] -> 9 | W5: =TEXT(tblMaster[[#This Row],[Order_Date]],"mmmm") -> July | X5: =MONTH(tblMaster[[#This Row],[Order_Date]]) -> 7 | Y5: ="Q"&ROUNDUP(tblMaster[[#This Row],[Month Number]]/3,0) -> Q3 | Z5: =YEAR(tblMaster[[#This Row],[Order_Date]]) -> 2023 | AA5: =TEXT(DAY(tblMaster[[#This Row],[Order_Date]]),"dddd") -> Tuesday | AB5: =IF(tblMaster[[#This Row],[Revenue]]>=5000,"High",IF(tblMaster[[#This Row],[Revenue]]<2000,"Low","Medium")) -> High
A6: 5 | B6: C078 | C6: 58 | D6: 2 | E6: 44968 | F6: 0.82277778 | G6: 44975 | H6: 0.46449074 | I6: Rajkot | J6: Valentine's Day | K6: =_xlfn.XLOOKUP(tblMaster[[#This Row],[Customer_ID]],tblCustomers[Customer_ID],tblCustomers[City],"Not Found",0) -> Bhubaneswar | L6: =_xlfn.XLOOKUP(tblMaster[[#This Row],[Customer_ID]],tblCustomers[Customer_ID],tblCustomers[Name],"Not Found",0) -> Jivika Rajan | M6: =_xlfn.XLOOKUP(tblMaster[[#This Row],[Customer_ID]],tblCustomers[Customer_ID],tblCustomers[Gender],"Not Found",0) -> Female | N6: =_xlfn.XLOOKUP(tblMaster[[#This Row],[Product_ID]],tblProducts[Product_ID],tblProducts[Product_Name],"Not Found",0) -> Sed Pack | O6: =_xlfn.XLOOKUP(tblMaster[[#This Row],[Product_ID]],tblProducts[Product_ID],tblProducts[Category],"Not Found",0) -> Cake | P6: =_xlfn.XLOOKUP(tblMaster[[#This Row],[Product_ID]],tblProducts[Product_ID],tblProducts[Occasion],"Not Found",0) -> Valentine's Day | Q6: =_xlfn.XLOOKUP(tblMaster[[#This Row],[Product_ID]],tblProducts[Product_ID],tblProducts[Price (INR)],"Not Found",0) -> 1492 | R6: =tblMaster[[#This Row],[Price]]*tblMaster[[#This Row],[Quantity]] -> 2984 | S6: =tblMaster[[#This Row],[Price]]*0.7*tblMaster[[#This Row],[Quantity]] -> 2088.8 | T6: =tblMaster[[#This Row],[Revenue]]-tblMaster[[#This Row],[Estimated Cost (at 70%) ]] -> 895.2 | U6: =tblMaster[[#This Row],[Profit]]/tblMaster[[#This Row],[Revenue]] -> 0.3 | V6: =tblMaster[[#This Row],[Delivery_Date]]-tblMaster[[#This Row],[Order_Date]] -> 7 | W6: =TEXT(tblMaster[[#This Row],[Order_Date]],"mmmm") -> February | X6: =MONTH(tblMaster[[#This Row],[Order_Date]]) -> 2 | Y6: ="Q"&ROUNDUP(tblMaster[[#This Row],[Month Number]]/3,0) -> Q1 | Z6: =YEAR(tblMaster[[#This Row],[Order_Date]]) -> 2023 | AA6: =TEXT(DAY(tblMaster[[#This Row],[Order_Date]]),"dddd") -> Wednesday | AB6: =IF(tblMaster[[#This Row],[Revenue]]>=5000,"High",IF(tblMaster[[#This Row],[Revenue]]<2000,"Low","Medium")) -> Medium
A7: 6 | B7: C040 | C7: 28 | D7: 4 | E7: 45158 | F7: 0.92471065 | G7: 45164 | H7: 0.79636574 | I7: Sirsa | J7: Raksha Bandhan | K7: =_xlfn.XLOOKUP(tblMaster[[#This Row],[Customer_ID]],tblCustomers[Customer_ID],tblCustomers[City],"Not Found",0) -> Pallavaram | L7: =_xlfn.XLOOKUP(tblMaster[[#This Row],[Customer_ID]],tblCustomers[Customer_ID],tblCustomers[Name],"Not Found",0) -> Hazel Mangat | M7: =_xlfn.XLOOKUP(tblMaster[[#This Row],[Customer_ID]],tblCustomers[Customer_ID],tblCustomers[Gender],"Not Found",0) -> Female | N7: =_xlfn.XLOOKUP(tblMaster[[#This Row],[Product_ID]],tblProducts[Product_ID],tblProducts[Product_Name],"Not Found",0) -> Velit Set | O7: =_xlfn.XLOOKUP(tblMaster[[#This Row],[Product_ID]],tblProducts[Product_ID],tblProducts[Category],"Not Found",0) -> Sweets | P7: =_xlfn.XLOOKUP(tblMaster[[#This Row],[Product_ID]],tblProducts[Product_ID],tblProducts[Occasion],"Not Found",0) -> Raksha Bandhan | Q7: =_xlfn.XLOOKUP(tblMaster[[#This Row],[Product_ID]],tblProducts[Product_ID],tblProducts[Price (INR)],"Not Found",0) -> 1778 | R7: =tblMaster[[#This Row],[Price]]*tblMaster[[#This Row],[Quantity]] -> 7112 | S7: =tblMaster[[#This Row],[Price]]*0.7*tblMaster[[#This Row],[Quantity]] -> 4978.4 | T7: =tblMaster[[#This Row],[Revenue]]-tblMaster[[#This Row],[Estimated Cost (at 70%) ]] -> 2133.6 | U7: =tblMaster[[#This Row],[Profit]]/tblMaster[[#This Row],[Revenue]] -> 0.3 | V7: =tblMaster[[#This Row],[Delivery_Date]]-tblMaster[[#This Row],[Order_Date]] -> 6 | W7: =TEXT(tblMaster[[#This Row],[Order_Date]],"mmmm") -> August | X7: =MONTH(tblMaster[[#This Row],[Order_Date]]) -> 8 | Y7: ="Q"&ROUNDUP(tblMaster[[#This Row],[Month Number]]/3,0) -> Q3 | Z7: =YEAR(tblMaster[[#This Row],[Order_Date]]) -> 2023 | AA7: =TEXT(DAY(tblMaster[[#This Row],[Order_Date]]),"dddd") -> Friday | AB7: =IF(tblMaster[[#This Row],[Revenue]]>=5000,"High",IF(tblMaster[[#This Row],[Revenue]]<2000,"Low","Medium")) -> High
A8: 7 | B8: C009 | C8: 45 | D8: 2 | E8: 45054 | F8: 0.07306713 | G8: 45059 | H8: 0.42172454 | I8: Nanded | J8: Birthday | K8: =_xlfn.XLOOKUP(tblMaster[[#This Row],[Customer_ID]],tblCustomers[Customer_ID],tblCustomers[City],"Not Found",0) -> Madurai | L8: =_xlfn.XLOOKUP(tblMaster[[#This Row],[Customer_ID]],tblCustomers[Customer_ID],tblCustomers[Name],"Not Found",0) -> Ritvik Borah | M8: =_xlfn.XLOOKUP(tblMaster[[#This Row],[Customer_ID]],tblCustomers[Customer_ID],tblCustomers[Gender],"Not Found",0) -> Female | N8: =_xlfn.XLOOKUP(tblMaster[[#This Row],[Product_ID]],tblProducts[Product_ID],tblProducts[Product_Name],"Not Found",0) -> Iusto Set | O8: =_xlfn.XLOOKUP(tblMaster[[#This Row],[Product_ID]],tblProducts[Product_ID],tblProducts[Category],"Not Found",0) -> Raksha Bandhan | P8: =_xlfn.XLOOKUP(tblMaster[[#This Row],[Product_ID]],tblProducts[Product_ID],tblProducts[Occasion],"Not Found",0) -> Birthday | Q8: =_xlfn.XLOOKUP(tblMaster[[#This Row],[Product_ID]],tblProducts[Product_ID],tblProducts[Price (INR)],"Not Found",0) -> 722 | R8: =tblMaster[[#This Row],[Price]]*tblMaster[[#This Row],[Quantity]] -> 1444 | S8: =tblMaster[[#This Row],[Price]]*0.7*tblMaster[[#This Row],[Quantity]] -> 1010.8 | T8: =tblMaster[[#This Row],[Revenue]]-tblMaster[[#This Row],[Estimated Cost (at 70%) ]] -> 433.2 | U8: =tblMaster[[#This Row],[Profit]]/tblMaster[[#This Row],[Revenue]] -> 0.3 | V8: =tblMaster[[#This Row],[Delivery_Date]]-tblMaster[[#This Row],[Order_Date]] -> 5 | W8: =TEXT(tblMaster[[#This Row],[Order_Date]],"mmmm") -> May | X8: =MONTH(tblMaster[[#This Row],[Order_Date]]) -> 5 | Y8: ="Q"&ROUNDUP(tblMaster[[#This Row],[Month Number]]/3,0) -> Q2 | Z8: =YEAR(tblMaster[[#This Row],[Order_Date]]) -> 2023 | AA8: =TEXT(DAY(tblMaster[[#This Row],[Order_Date]]),"dddd") -> Sunday | AB8: =IF(tblMaster[[#This Row],[Revenue]]>=5000,"High",IF(tblMaster[[#This Row],[Revenue]]<2000,"Low","Medium")) -> Low
A9: 8 | B9: C097 | C9: 43 | D9: 3 | E9: 45238 | F9: 0.8055787 | G9: 45244 | H9: 0.36440972 | I9: Morena | J9: Diwali | K9: =_xlfn.XLOOKUP(tblMaster[[#This Row],[Customer_ID]],tblCustomers[Customer_ID],tblCustomers[City],"Not Found",0) -> Sri Ganganagar | L9: =_xlfn.XLOOKUP(tblMaster[[#This Row],[Customer_ID]],tblCustomers[Customer_ID],tblCustomers[Name],"Not Found",0) -> Nakul Randhawa | M9: =_xlfn.XLOOKUP(tblMaster[[#This Row],[Customer_ID]],tblCustomers[Customer_ID],tblCustomers[Gender],"Not Found",0) -> Female | N9: =_xlfn.XLOOKUP(tblMaster[[#This Row],[Product_ID]],tblProducts[Product_ID],tblProducts[Product_Name],"Not Found",0) -> Quisquam Pack | O9: =_xlfn.XLOOKUP(tblMaster[[#This Row],[Product_ID]],tblProducts[Product_ID],tblProducts[Category],"Not Found",0) -> Raksha Bandhan | P9: =_xlfn.XLOOKUP(tblMaster[[#This Row],[Product_ID]],tblProducts[Product_ID],tblProducts[Occasion],"Not Found",0) -> Diwali | Q9: =_xlfn.XLOOKUP(tblMaster[[#This Row],[Product_ID]],tblProducts[Product_ID],tblProducts[Price (INR)],"Not Found",0) -> 750 | R9: =tblMaster[[#This Row],[Price]]*tblMaster[[#This Row],[Quantity]] -> 2250 | S9: =tblMaster[[#This Row],[Price]]*0.7*tblMaster[[#This Row],[Quantity]] -> 1575 | T9: =tblMaster[[#This Row],[Revenue]]-tblMaster[[#This Row],[Estimated Cost (at 70%) ]] -> 675 | U9: =tblMaster[[#This Row],[Profit]]/tblMaster[[#This Row],[Revenue]] -> 0.3 | V9: =tblMaster[[#This Row],[Delivery_Date]]-tblMaster[[#This Row],[Order_Date]] -> 6 | W9: =TEXT(tblMaster[[#This Row],[Order_Date]],"mmmm") -> November | X9: =MONTH(tblMaster[[#This Row],[Order_Date]]) -> 11 | Y9: ="Q"&ROUNDUP(tblMaster[[#This Row],[Month Number]]/3,0) -> Q4 | Z9: =YEAR(tblMaster[[#This Row],[Order_Date]]) -> 2023 | AA9: =TEXT(DAY(tblMaster[[#This Row],[Order_Date]]),"dddd") -> Sunday | AB9: =IF(tblMaster[[#This Row],[Revenue]]>=5000,"High",IF(tblMaster[[#This Row],[Revenue]]<2000,"Low","Medium")) -> Medium
A10: 9 | B10: C044 | C10: 27 | D10: 4 | E10: 45158 | F10: 0.98600694 | G10: 45167 | H10: 0.99993056 | I10: Rajkot | J10: Raksha Bandhan | K10: =_xlfn.XLOOKUP(tblMaster[[#This Row],[Customer_ID]],tblCustomers[Customer_ID],tblCustomers[City],"Not Found",0) -> Agra | L10: =_xlfn.XLOOKUP(tblMaster[[#This Row],[Customer_ID]],tblCustomers[Customer_ID],tblCustomers[Name],"Not Found",0) -> Seher Mann | M10: =_xlfn.XLOOKUP(tblMaster[[#This Row],[Customer_ID]],tblCustomers[Customer_ID],tblCustomers[Gender],"Not Found",0) -> Male | N10: =_xlfn.XLOOKUP(tblMaster[[#This Row],[Product_ID]],tblProducts[Product_ID],tblProducts[Product_Name],"Not Found",0) -> Architecto Gift | O10: =_xlfn.XLOOKUP(tblMaster[[#This Row],[Product_ID]],tblProducts[Product_ID],tblProducts[Category],"Not Found",0) -> Cake | P10: =_xlfn.XLOOKUP(tblMaster[[#This Row],[Product_ID]],tblProducts[Product_ID],tblProducts[Occasion],"Not Found",0) -> Raksha Bandhan | Q10: =_xlfn.XLOOKUP(tblMaster[[#This Row],[Product_ID]],tblProducts[Product_ID],tblProducts[Price (INR)],"Not Found",0) -> 548 | R10: =tblMaster[[#This Row],[Price]]*tblMaster[[#This Row],[Quantity]] -> 2192 | S10: =tblMaster[[#This Row],[Price]]*0.7*tblMaster[[#This Row],[Quantity]] -> 1534.4 | T10: =tblMaster[[#This Row],[Revenue]]-tblMaster[[#This Row],[Estimated Cost (at 70%) ]] -> 657.6 | U10: =tblMaster[[#This Row],[Profit]]/tblMaster[[#This Row],[Revenue]] -> 0.3 | V10: =tblMaster[[#This Row],[Delivery_Date]]-tblMaster[[#This Row],[Order_Date]] -> 9 | W10: =TEXT(tblMaster[[#This Row],[Order_Date]],"mmmm") -> August | X10: =MONTH(tblMaster[[#This Row],[Order_Date]]) -> 8 | Y10: ="Q"&ROUNDUP(tblMaster[[#This Row],[Month Number]]/3,0) -> Q3 | Z10: =YEAR(tblMaster[[#This Row],[Order_Date]]) -> 2023 | AA10: =TEXT(DAY(tblMaster[[#This Row],[Order_Date]]),"dddd") -> Friday | AB10: =IF(tblMaster[[#This Row],[Revenue]]>=5000,"High",IF(tblMaster[[#This Row],[Revenue]]<2000,"Low","Medium")) -> Medium
A11: 10 | B11: C099 | C11: 56 | D11: 3 | E11: 44983 | F11: 0.012106481 | G11: 44993 | H11: 0.86646991 | I11: Ambala | J11: Anniversary | K11: =_xlfn.XLOOKUP(tblMaster[[#This Row],[Customer_ID]],tblCustomers[Customer_ID],tblCustomers[City],"Not Found",0) -> Dhanbad | L11: =_xlfn.XLOOKUP(tblMaster[[#This Row],[Customer_ID]],tblCustomers[Customer_ID],tblCustomers[Name],"Not Found",0) -> Ranbir Loyal | M11: =_xlfn.XLOOKUP(tblMaster[[#This Row],[Customer_ID]],tblCustomers[Customer_ID],tblCustomers[Gender],"Not Found",0) -> Female | N11: =_xlfn.XLOOKUP(tblMaster[[#This Row],[Product_ID]],tblProducts[Product_ID],tblProducts[Product_Name],"Not Found",0) -> Quia Gift | O11: =_xlfn.XLOOKUP(tblMaster[[#This Row],[Product_ID]],tblProducts[Product_ID],tblProducts[Category],"Not Found",0) -> Raksha Bandhan | P11: =_xlfn.XLOOKUP(tblMaster[[#This Row],[Product_ID]],tblProducts[Product_ID],tblProducts[Occasion],"Not Found",0) -> Anniversary | Q11: =_xlfn.XLOOKUP(tblMaster[[#This Row],[Product_ID]],tblProducts[Product_ID],tblProducts[Price (INR)],"Not Found",0) -> 1272 | R11: =tblMaster[[#This Row],[Price]]*tblMaster[[#This Row],[Quantity]] -> 3816 | S11: =tblMaster[[#This Row],[Price]]*0.7*tblMaster[[#This Row],[Quantity]] -> 2671.2 | T11: =tblMaster[[#This Row],[Revenue]]-tblMaster[[#This Row],[Estimated Cost (at 70%) ]] -> 1144.8 | U11: =tblMaster[[#This Row],[Profit]]/tblMaster[[#This Row],[Revenue]] -> 0.3 | V11: =tblMaster[[#This Row],[Delivery_Date]]-tblMaster[[#This Row],[Order_Date]] -> 10 | W11: =TEXT(tblMaster[[#This Row],[Order_Date]],"mmmm") -> February | X11: =MONTH(tblMaster[[#This Row],[Order_Date]]) -> 2 | Y11: ="Q"&ROUNDUP(tblMaster[[#This Row],[Month Number]]/3,0) -> Q1 | Z11: =YEAR(tblMaster[[#This Row],[Order_Date]]) -> 2023 | AA11: =TEXT(DAY(tblMaster[[#This Row],[Order_Date]]),"dddd") -> Thursday | AB11: =IF(tblMaster[[#This Row],[Revenue]]>=5000,"High",IF(tblMaster[[#This Row],[Revenue]]<2000,"Low","Medium")) -> Medium
A12: 11 | B12: C065 | C12: 16 | D12: 4 | E12: 44987 | F12: 0.84369213 | G12: 44988 | H12: 0.97207176 | I12: Belgaum | J12: Holi | K12: =_xlfn.XLOOKUP(tblMaster[[#This Row],[Customer_ID]],tblCustomers[Customer_ID],tblCustomers[City],"Not Found",0) -> North Dumdum | L12: =_xlfn.XLOOKUP(tblMaster[[#This Row],[Customer_ID]],tblCustomers[Customer_ID],tblCustomers[Name],"Not Found",0) -> Badal Vora | M12: =_xlfn.XLOOKUP(tblMaster[[#This Row],[Customer_ID]],tblCustomers[Customer_ID],tblCustomers[Gender],"Not Found",0) -> Male | N12: =_xlfn.XLOOKUP(tblMaster[[#This Row],[Product_ID]],tblProducts[Product_ID],tblProducts[Product_Name],"Not Found",0) -> Ut Pack | O12: =_xlfn.XLOOKUP(tblMaster[[#This Row],[Product_ID]],tblProducts[Product_ID],tblProducts[Category],"Not Found",0) -> Sweets | P12: =_xlfn.XLOOKUP(tblMaster[[#This Row],[Product_ID]],tblProducts[Product_ID],tblProducts[Occasion],"Not Found",0) -> Holi | Q12: =_xlfn.XLOOKUP(tblMaster[[#This Row],[Product_ID]],tblProducts[Product_ID],tblProducts[Price (INR)],"Not Found",0) -> 1721 | R12: =tblMaster[[#This Row],[Price]]*tblMaster[[#This Row],[Quantity]] -> 6884 | S12: =tblMaster[[#This Row],[Price]]*0.7*tblMaster[[#This Row],[Quantity]] -> 4818.8 | T12: =tblMaster[[#This Row],[Revenue]]-tblMaster[[#This Row],[Estimated Cost (at 70%) ]] -> 2065.2 | U12: =tblMaster[[#This Row],[Profit]]/tblMaster[[#This Row],[Revenue]] -> 0.3 | V12: =tblMaster[[#This Row],[Delivery_Date]]-tblMaster[[#This Row],[Order_Date]] -> 1 | W12: =TEXT(tblMaster[[#This Row],[Order_Date]],"mmmm") -> March | X12: =MONTH(tblMaster[[#This Row],[Order_Date]]) -> 3 | Y12: ="Q"&ROUNDUP(tblMaster[[#This Row],[Month Number]]/3,0) -> Q1 | Z12: =YEAR(tblMaster[[#This Row],[Order_Date]]) -> 2023 | AA12: =TEXT(DAY(tblMaster[[#This Row],[Order_Date]]),"dddd") -> Monday | AB12: =IF(tblMaster[[#This Row],[Revenue]]>=5000,"High",IF(tblMaster[[#This Row],[Revenue]]<2000,"Low","Medium")) -> High
A13: 12 | B13: C097 | C13: 38 | D13: 3 | E13: 45119 | F13: 0.35342593 | G13: 45127 | H13: 0.98260417 | I13: Karnal | J13: Birthday | K13: =_xlfn.XLOOKUP(tblMaster[[#This Row],[Customer_ID]],tblCustomers[Customer_ID],tblCustomers[City],"Not Found",0) -> Sri Ganganagar | L13: =_xlfn.XLOOKUP(tblMaster[[#This Row],[Customer_ID]],tblCustomers[Customer_ID],tblCustomers[Name],"Not Found",0) -> Nakul Randhawa | M13: =_xlfn.XLOOKUP(tblMaster[[#This Row],[Customer_ID]],tblCustomers[Customer_ID],tblCustomers[Gender],"Not Found",0) -> Female | N13: =_xlfn.XLOOKUP(tblMaster[[#This Row],[Product_ID]],tblProducts[Product_ID],tblProducts[Product_Name],"Not Found",0) -> Mollitia Set | O13: =_xlfn.XLOOKUP(tblMaster[[#This Row],[Product_ID]],tblProducts[Product_ID],tblProducts[Category],"Not Found",0) -> Cake | P13: =_xlfn.XLOOKUP(tblMaster[[#This Row],[Product_ID]],tblProducts[Product_ID],tblProducts[Occasion],"Not Found",0) -> Birthday | Q13: =_xlfn.XLOOKUP(tblMaster[[#This Row],[Product_ID]],tblProducts[Product_ID],tblProducts[Price (INR)],"Not Found",0) -> 562 | R13: =tblMaster[[#This Row],[Price]]*tblMaster[[#This Row],[Quantity]] -> 1686 | S13: =tblMaster[[#This Row],[Price]]*0.7*tblMaster[[#This Row],[Quantity]] -> 1180.2 | T13: =tblMaster[[#This Row],[Revenue]]-tblMaster[[#This Row],[Estimated Cost (at 70%) ]] -> 505.8 | U13: =tblMaster[[#This Row],[Profit]]/tblMaster[[#This Row],[Revenue]] -> 0.3 | V13: =tblMaster[[#This Row],[Delivery_Date]]-tblMaster[[#This Row],[Order_Date]] -> 8 | W13: =TEXT(tblMaster[[#This Row],[Order_Date]],"mmmm") -> July | X13: =MONTH(tblMaster[[#This Row],[Order_Date]]) -> 7 | Y13: ="Q"&ROUNDUP(tblMaster[[#This Row],[Month Number]]/3,0) -> Q3 | Z13: =YEAR(tblMaster[[#This Row],[Order_Date]]) -> 2023 | AA13: =TEXT(DAY(tblMaster[[#This Row],[Order_Date]]),"dddd") -> Thursday | AB13: =IF(tblMaster[[#This Row],[Revenue]]>=5000,"High",IF(tblMaster[[#This Row],[Revenue]]<2000,"Low","Medium")) -> Low
... A1001: 1000 | B1001: C012 | C1001: 27 | D1001: 4 | E1001: 45163 | F1001: 0.05744213 | G1001: 45169 | H1001: 0.2902662 | I1001: Tadepalligudem | J1001: Raksha Bandhan | K1001: =_xlfn.XLOOKUP(tblMaster[[#This Row],[Customer_ID]],tblCustomers[Customer_ID],tblCustomers[City],"Not Found",0) -> Bilaspur | L1001: =_xlfn.XLOOKUP(tblMaster[[#This Row],[Customer_ID]],tblCustomers[Customer_ID],tblCustomers[Name],"Not Found",0) -> Onkar Mangat | M1001: =_xlfn.XLOOKUP(tblMaster[[#This Row],[Customer_ID]],tblCustomers[Customer_ID],tblCustomers[Gender],"Not Found",0) -> Male | N1001: =_xlfn.XLOOKUP(tblMaster[[#This Row],[Product_ID]],tblProducts[Product_ID],tblProducts[Product_Name],"Not Found",0) -> Architecto Gift | O1001: =_xlfn.XLOOKUP(tblMaster[[#This Row],[Product_ID]],tblProducts[Product_ID],tblProducts[Category],"Not Found",0) -> Cake | P1001: =_xlfn.XLOOKUP(tblMaster[[#This Row],[Product_ID]],tblProducts[Product_ID],tblProducts[Occasion],"Not Found",0) -> Raksha Bandhan | Q1001: =_xlfn.XLOOKUP(tblMaster[[#This Row],[Product_ID]],tblProducts[Product_ID],tblProducts[Price (INR)],"Not Found",0) -> 548 | R1001: =tblMaster[[#This Row],[Price]]*tblMaster[[#This Row],[Quantity]] -> 2192 | S1001: =tblMaster[[#This Row],[Price]]*0.7*tblMaster[[#This Row],[Quantity]] -> 1534.4 | T1001: =tblMaster[[#This Row],[Revenue]]-tblMaster[[#This Row],[Estimated Cost (at 70%) ]] -> 657.6 | U1001: =tblMaster[[#This Row],[Profit]]/tblMaster[[#This Row],[Revenue]] -> 0.3 | V1001: =tblMaster[[#This Row],[Delivery_Date]]-tblMaster[[#This Row],[Order_Date]] -> 6 | W1001: =TEXT(tblMaster[[#This Row],[Order_Date]],"mmmm") -> August | X1001: =MONTH(tblMaster[[#This Row],[Order_Date]]) -> 8 | Y1001: ="Q"&ROUNDUP(tblMaster[[#This Row],[Month Number]]/3,0) -> Q3 | Z1001: =YEAR(tblMaster[[#This Row],[Order_Date]]) -> 2023 | AA1001: =TEXT(DAY(tblMaster[[#This Row],[Order_Date]]),"dddd") -> Wednesday | AB1001: =IF(tblMaster[[#This Row],[Revenue]]>=5000,"High",IF(tblMaster[[#This Row],[Revenue]]<2000,"Low","Medium")) -> Medium

Sheet Pivot Tables
A3: KPIs | G3: Order Size | H3: Total Orders
A4: Total Orders | B4: 1000 | G4: High | H4: 257
A5: Total Revenue | B5: 3520984 | G5: Low | H5: 356
A6: Total Profit | B6: 1056295.2 | G6: Medium | H6: 387
A7: Average Order Value | B7: 3520.984 | G7: Grand Total | H7: 1000
A13: Occasion | B13: Total Revenue | C13: Total Profit | G13: Occasion | H13: Average Delivery Time
A14: All Occasions | B14: 586176 | C14: 175852.8 | G14: Holi | H14: 5.7777778
A15: Anniversary | B15: 674634 | C15: 202390.2 | G15: All Occasions | H15: 5.7222222
A16: Birthday | B16: 408194 | C16: 122458.2 | G16: Raksha Bandhan | H16: 5.6893939
A17: Diwali | B17: 313783 | C17: 94134.9 | G17: Anniversary | H17: 5.5170732
A18: Holi | B18: 574682 | C18: 172404.6 | G18: Birthday | H18: 5.4630872
A19: Raksha Bandhan | B19: 631585 | C19: 189475.5 | G19: Valentine's Day | H19: 5.3362832
A20: Valentine's Day | B20: 331930 | C20: 99579 | G20: Diwali | H20: 4.9473684
A21: Grand Total | B21: 3520984 | C21: 1056295.2 | G21: Grand Total | H21: 5.53
A25: Category | B25: Total Revenue | C25: Total Profit | G25: Category | H25: Average Delivery Time
A26: Cake | B26: 329862 | C26: 98958.6 | G26: Cake | H26: 6.0169492
A27: Colors | B27: 1005645 | C27: 301693.5 | G27: Sweets | H27: 5.7251462
A28: Mugs | B28: 201151 | C28: 60345.3 | G28: Colors | H28: 5.6336996
A29: Plants | B29: 212281 | C29: 63684.3 | G29: Raksha Bandhan | H29: 5.3838384
A30: Raksha Bandhan | B30: 297372 | C30: 89211.6 | G30: Mugs | H30: 5.3513514
A31: Soft Toys | B31: 740831 | C31: 222249.3 | G31: Soft Toys | H31: 5.2289157
A32: Sweets | B32: 733842 | C32: 220152.6 | G32: Plants | H32: 5.1111111
A33: Grand Total | B33: 3520984 | C33: 1056295.2 | G33: Grand Total | H33: 5.53
A37: Month | B37: Total Revenue | C37: Total Profit | G37: Weekday | H37: Total Revenue | I37: Total Profit
A38: August | B38: 737389 | C38: 221216.7 | G38: Monday | H38: 449717 | I38: 134915.1
A39: February | B39: 704509 | C39: 211352.7 | G39: Tuesday | H39: 423119 | I39: 126935.7
A40: March | B40: 511823 | C40: 153546.9 | G40: Wednesday | H40: 475516 | I40: 142654.8
A41: November | B41: 449169 | C41: 134750.7 | G41: Thursday | H41: 507392 | I41: 152217.6
A42: June | B42: 157913 | C42: 47373.9 | G42: Friday | H42: 501552 | I42: 150465.6
A43: October | B43: 151619 | C43: 45485.7 | G43: Saturday | H43: 521219 | I43: 156365.7
A44: May | B44: 150346 | C44: 45103.8 | G44: Sunday | H44: 642469 | I44: 192740.7
A45: December | B45: 149591 | C45: 44877.3 | G45: Grand Total | H45: 3520984 | I45: 1056295.2
A46: April | B46: 140393 | C46: 42117.9
A47: September | B47: 136938 | C47: 41081.4
A48: July | B48: 135826 | C48: 40747.8
A49: January | B49: 95468 | C49: 28640.4
A50: Grand Total | B50: 3520984 | C50: 1056295.2
A55: Product | B55: Total Revenue | C55: Total Profit | G55: Product | H55: Average Delivery Time
A56: Accusantium Gift | B56: 10619 | C56: 3185.7 | G56: Accusantium Gift | H56: 6.4
A57: Accusantium Set | B57: 61149 | C57: 18344.7 | G57: Accusantium Set | H57: 5.0625
...

Sheet Dashboard
G1: Sales Performance Analysis Dashboard
A3: Total Revenue | C3: Total Profit | E3: Total Orders | G3: Average Order Value | I3: Average Delivery Days | K3: Profit Margin | M3: Average Cost | O3: Average Price | Q3: Average Quantity
A4: =GETPIVOTDATA("Total Revenue",'Pivot Tables'!$A$3) -> 3520984 | C4: =GETPIVOTDATA("Total Profit",'Pivot Tables'!$A$3) -> 1056295.2 | E4: =GETPIVOTDATA("Total Orders",'Pivot Tables'!$A$3) -> 1000 | G4: =GETPIVOTDATA("Average Order Value",'Pivot Tables'!$A$3) -> 3520.984 | I4: =GETPIVOTDATA("Delivery Time",'Pivot Tables'!$G$25) -> 5.53 | K4: =GETPIVOTDATA("Total Profit",'Pivot Tables'!$A$25)/GETPIVOTDATA("Total Revenue",'Pivot Tables'!$A$25) -> 0.3 | M4: =SUM('Cleaned Data'!S2:S1001)/1000 -> 2464.6888 | O4: =SUM('Cleaned Data'!Q2:Q1001)/1000 -> 1156.108 | Q4: =SUM('Cleaned Data'!D2:D1001)/1000 -> 3.045
